<?xml version="1.0" ?>
<!-- =================================================================================== -->
<!-- |    This document was autogenerated by xacro from usn_drone_gazebo.urdf.xacro    | -->
<!-- |    EDITING THIS FILE BY HAND IS NOT RECOMMENDED                                 | -->
<!-- =================================================================================== -->
<!-- Basic WAM-V with gazebo plugins for dynamics -->
<robot name="WAM-V">
  <!-- === Batteries === >
  <xacro:include filename="$(find usn_drone_description)/urdf/battery.xacro"/>
  <xacro:battery prefix="left" position="0 1 0.45" orientation="0 0 0"/>
  <xacro:battery prefix="right" position="0 -1 0.45" orientation="0 0 0"/-->
  <material name="blue">
    <color rgba="0.4 0.5 0.8 0.9"/>
  </material>
  <material name="black">
    <color rgba="0 0 0 1"/>
  </material>
  <material name="white">
    <color rgba="1 1 1 1"/>
  </material>
  <link name="usn_drone/base_link">
    <inertial>
      <origin rpy="0 0 0" xyz="0.057087 6.73379999999908E-05 -0.15067"/>
      <mass value="15.678"/>
      <inertia ixx="0.91176" ixy="0.00336300000000002" ixz="-0.30208" iyy="4.0991" iyz="0.000128790000000019" izz="4.4173"/>
    </inertial>
    <visual>
      <origin rpy="1.5707963267949 0 0" xyz="0 0 0"/>
      <geometry>
        <mesh filename="package://usn_drone/meshes/usn_drone.STL"/>
      </geometry>
      <material name="blue"/>
    </visual>
    <collision>
      <origin rpy="1.5707963267949 0 0" xyz="0 0 0"/>
      <geometry>
        <mesh filename="package://usn_drone/meshes/usn_drone.STL"/>
      </geometry>
    </collision>
  </link>
  <link name="usn_drone/left_engine_link">
    <visual>
      <geometry>
        <mesh filename="package://usn_drone_description/models/engine/mesh/engine.dae"/>
      </geometry>
    </visual>
    <collision name="left_engine_vertical_axis_collision">
      <origin rpy="0 0 0" xyz="-0.16 0 -0.24"/>
      <geometry>
        <box size="0.2 0.15 0.83"/>
      </geometry>
    </collision>
    <collision name="left_engine_rear_end_collision">
      <origin rpy="0 0 0" xyz="-0.34 0 0.12"/>
      <geometry>
        <box size="0.12 0.15 0.12"/>
      </geometry>
    </collision>
    <inertial>
      <mass value="15"/>
      <inertia ixx="0.889245" ixy="0.0" ixz="0.0" iyy="0.911125" iyz="0.0" izz="0.078125"/>
    </inertial>
  </link>
  <link name="usn_drone/left_propeller_link">
    <visual>
      <geometry>
        <mesh filename="package://usn_drone_description/models/propeller/mesh/propeller.dae"/>
      </geometry>
    </visual>
    <collision name="left_propeller_collision">
      <origin rpy="0 1.57 0" xyz="-0.08 0 0"/>
      <geometry>
        <cylinder length="0.18" radius="0.24"/>
      </geometry>
    </collision>
    <inertial>
      <mass value="0.5"/>
      <inertia ixx="0.008545" ixy="0.0" ixz="0.0" iyy="0.008545" iyz="0.0" izz="0.0144"/>
    </inertial>
  </link>
  <joint name="usn_drone/left_chasis_engine_joint" type="revolute">
    <axis xyz="0 0 1"/>
    <limit effort="10" lower="-3.141592653589793" upper="3.141592653589793" velocity="10"/>
    <origin rpy="0 0 0" xyz="-2.373776 1.027135 0.318237"/>
    <parent link="usn_drone/base_link"/>
    <child link="usn_drone/left_engine_link"/>
  </joint>
  <joint name="usn_drone/left_engine_propeller_joint" type="continuous">
    <axis rpy="0 0 0" xyz="1 0 0"/>
    <parent link="usn_drone/left_engine_link"/>
    <child link="usn_drone/left_propeller_link"/>
    <origin rpy="0 0 0" xyz="-0.278156 0 -0.509371"/>
    <limit effort="100" velocity="100"/>
    <dynamics damping="0.05" friction="0.05"/>
  </joint>
  <link name="usn_drone/right_engine_link">
    <visual>
      <geometry>
        <mesh filename="package://usn_drone_description/models/engine/mesh/engine.dae"/>
      </geometry>
    </visual>
    <collision name="right_engine_vertical_axis_collision">
      <origin rpy="0 0 0" xyz="-0.16 0 -0.24"/>
      <geometry>
        <box size="0.2 0.15 0.83"/>
      </geometry>
    </collision>
    <collision name="right_engine_rear_end_collision">
      <origin rpy="0 0 0" xyz="-0.34 0 0.12"/>
      <geometry>
        <box size="0.12 0.15 0.12"/>
      </geometry>
    </collision>
    <inertial>
      <mass value="15"/>
      <inertia ixx="0.889245" ixy="0.0" ixz="0.0" iyy="0.911125" iyz="0.0" izz="0.078125"/>
    </inertial>
  </link>
  <link name="usn_drone/right_propeller_link">
    <visual>
      <geometry>
        <mesh filename="package://usn_drone_description/models/propeller/mesh/propeller.dae"/>
      </geometry>
    </visual>
    <collision name="right_propeller_collision">
      <origin rpy="0 1.57 0" xyz="-0.08 0 0"/>
      <geometry>
        <cylinder length="0.18" radius="0.24"/>
      </geometry>
    </collision>
    <inertial>
      <mass value="0.5"/>
      <inertia ixx="0.008545" ixy="0.0" ixz="0.0" iyy="0.008545" iyz="0.0" izz="0.0144"/>
    </inertial>
  </link>
  <joint name="usn_drone/right_chasis_engine_joint" type="revolute">
    <axis xyz="0 0 1"/>
    <limit effort="10" lower="-3.141592653589793" upper="3.141592653589793" velocity="10"/>
    <origin rpy="0 0 0" xyz="-2.373776 -1.027135 0.318237"/>
    <parent link="usn_drone/base_link"/>
    <child link="usn_drone/right_engine_link"/>
  </joint>
  <joint name="usn_drone/right_engine_propeller_joint" type="continuous">
    <axis rpy="0 0 0" xyz="1 0 0"/>
    <parent link="usn_drone/right_engine_link"/>
    <child link="usn_drone/right_propeller_link"/>
    <origin rpy="0 0 0" xyz="-0.278156 0 -0.509371"/>
    <limit effort="100" velocity="100"/>
    <dynamics damping="0.05" friction="0.05"/>
  </joint>
  <gazebo>
    <plugin filename="libusv_gazebo_thrust_plugin.so" name="usn_drone_gazebo_thrust">
      <cmdTimeout>1.0</cmdTimeout>
      <publisherRate>100.0</publisherRate>
      <robotNamespace>usn_drone</robotNamespace>
      <thruster>
        <!-- Required Parameters -->
        <linkName>usn_drone/left_propeller_link</linkName>
        <propJointName>usn_drone/left_engine_propeller_joint</propJointName>
        <engineJointName>usn_drone/left_chasis_engine_joint</engineJointName>
        <cmdTopic>thrusters/left_thrust_cmd</cmdTopic>
        <angleTopic>thrusters/left_thrust_angle</angleTopic>
        <enableAngle>True</enableAngle>
        <!-- Optional Parameters -->
        <mappingType>1</mappingType>
        <maxCmd>1.0</maxCmd>
        <maxForceFwd>250.0</maxForceFwd>
        <maxForceRev>-100.0</maxForceRev>
        <maxAngle>1.5707963267948966</maxAngle>
      </thruster>
      <thruster>
        <!-- Required Parameters -->
        <linkName>usn_drone/right_propeller_link</linkName>
        <propJointName>usn_drone/right_engine_propeller_joint</propJointName>
        <engineJointName>usn_drone/right_chasis_engine_joint</engineJointName>
        <cmdTopic>thrusters/right_thrust_cmd</cmdTopic>
        <angleTopic>thrusters/right_thrust_angle</angleTopic>
        <enableAngle>True</enableAngle>
        <!-- Optional Parameters -->
        <mappingType>1</mappingType>
        <maxCmd>1.0</maxCmd>
        <maxForceFwd>250.0</maxForceFwd>
        <maxForceRev>-100.0</maxForceRev>
        <maxAngle>1.5707963267948966</maxAngle>
      </thruster>
    </plugin>
  </gazebo>
  <!--Gazebo Plugin for simulating WAM-V dynamics-->
  <gazebo>
    <plugin filename="libusv_gazebo_dynamics_plugin.so" name="usv_dynamics_usn_drone_dynamics_plugin">
      <bodyName>usn_drone/base_link</bodyName>
      <!-- Must be same as the ocean model!-->
      <waterLevel>0.25</waterLevel>
      <waterDensity>997.8</waterDensity>
      <!-- Added mass -->
      <xDotU>5.0</xDotU>
      <yDotV>5.0</yDotV>
      <nDotR>1.0</nDotR>
      <!-- Linear and quadratic drag -->
      <xU>51.3</xU>
      <xUU>72.4</xUU>
      <yV>40.0</yV>
      <yVV>0.0</yVV>
      <zW>500.0</zW>
      <kP>50.0</kP>
      <mQ>50.0</mQ>
      <nR>400.0</nR>
      <nRR>0.0</nRR>
      <!-- General dimensions -->
      <!--<boatArea>2.2</boatArea>-->
      <hullRadius>0.213</hullRadius>
      <boatWidth>2.4</boatWidth>
      <boatLength>4.9</boatLength>
      <!-- Length discretization, AKA, "N" -->
      <length_n>2</length_n>
      <!-- Wave model -->
      <wave_model>ocean_waves</wave_model>
    </plugin>
  </gazebo>
</robot>
