<?xml version="1.0"?>
<!-- Basic WAM-V with gazebo plugins for dynamics -->
<robot xmlns:xacro="http://ros.org/wiki/xacro" name="WAM-V">
  <xacro:arg name="locked" default="false" />
  <xacro:arg name="thruster_config" default="H" />
  <xacro:arg name="camera_enabled" default="true" />
  <xacro:arg name="gps_enabled" default="false" />
  <xacro:arg name="imu_enabled" default="false" />
  <xacro:arg name="lidar_enabled" default="false" />
  <xacro:arg name="ground_truth_enabled" default="false" />
  <xacro:arg name="vrx_sensors_enabled" default="false" />
  <xacro:arg name="pinger_enabled" default="false" />
  <xacro:arg name="ball_shooter_enabled" default="false" />
  <xacro:arg name="thruster_namespace" default="thrusters/" />
  <xacro:arg name="camera_namespace" default="cameras/" />

  <xacro:arg name="zed_namespace" default="zed/" />

  <xacro:arg name="sensor_namespace" default="sensors/" />
  <xacro:arg name="pinger_namespace" default="pingers/" />
  <xacro:arg name="shooter_namespace" default="shooters/" />
  <!-- Note: this is only used for some sensors that do not correctly use the
  robotNamespace parameter -->
  <xacro:arg name="namespace" default="usn_drone" />
  <xacro:property name="thruster_namespace" value="$(arg thruster_namespace)" scope="global" />
  <xacro:property name="camera_namespace" value="$(arg camera_namespace)" scope="global" />
  <xacro:property name="sensor_namespace" value="$(arg sensor_namespace)" scope="global" />
  <xacro:property name="pinger_namespace" value="$(arg pinger_namespace)" scope="global" />
  <xacro:property name="shooter_namespace" value="$(arg shooter_namespace)" scope="global" />
  <xacro:property name="namespace" value="$(arg namespace)" scope="global" />

  <!-- Sensor yaml file -->
  <xacro:arg name="yaml_component_generation" default="false" />
  <xacro:arg name="component_xacro_file" default="" />

  <!-- Thruster yaml file -->
  <xacro:arg name="yaml_thruster_generation" default="false" />
  <xacro:arg name="thruster_xacro_file" default="" />

  <!-- === The WAM-V platform === -->
  <xacro:include filename="$(find usn_drone_gazebo)/urdf/usn_drone_gazebo.xacro" />


  <!-- === Batteries === >
  <xacro:include filename="$(find usn_drone_description)/urdf/battery.xacro"/>
  <xacro:battery prefix="left" position="0 1 0.45" orientation="0 0 0"/>
  <xacro:battery prefix="right" position="0 -1 0.45" orientation="0 0 0"/-->


  <!-- === Thrusters === -->
  <!-- Use thruster yaml file if given -->
  <xacro:if value="$(arg yaml_thruster_generation)">
    <xacro:usn_drone_gazebo thruster_layout="$(arg thruster_xacro_file)" />
  </xacro:if>

  <!-- Otherwise, add thrusters based on thruster_config variable -->
  <xacro:unless value="$(arg yaml_thruster_generation)">
    <xacro:property name="thruster_conf" value="$(arg thruster_config)" />

    <!-- Default WAM-V with two aft thrusters -->
    <xacro:if value="${thruster_conf == 'H'}">
      <xacro:usn_drone_gazebo thruster_layout="$(find usn_drone_gazebo)/urdf/thruster_layouts/usn_drone_aft_thrusters.xacro" />
    </xacro:if>

    <!-- usn_drone with "T" thruster configuration -->
    <xacro:if value="${thruster_conf == 'T'}">
      <xacro:usn_drone_gazebo thruster_layout="$(find usn_drone_gazebo)/urdf/thruster_layouts/usn_drone_t_thrusters.xacro" />
    </xacro:if>

    <!-- usn_drone with "X" thruster configuration -->
    <xacro:if value="${thruster_conf == 'X'}">
      <xacro:usn_drone_gazebo thruster_layout="$(find usn_drone_gazebo)/urdf/thruster_layouts/usn_drone_x_thrusters.xacro" />
    </xacro:if>
  </xacro:unless>

  <!-- === Decide if we lock the robot to the world === -->
  <xacro:if value="$(arg locked)">
    <gazebo>
      <link name="usn_drone_external_link" />
      <joint name="usn_drone_external_pivot_joint" type="universal">
        <parent>usn_drone::usn_drone/base_link</parent>
        <child>usn_drone_external_link</child>
        <axis>
          <xyz>1 0 0</xyz>
        </axis>
        <axis2>
          <xyz>0 1 0</xyz>
        </axis2>
      </joint>
      <joint name="usn_drone_external_riser" type="prismatic">
        <parent>world</parent>
        <child>usn_drone_external_link</child>
        <axis>
          <limit>
            <lower>-3</lower>
            <upper>3</upper>
          </limit>
          <xyz>0 0 1</xyz>
        </axis>
      </joint>
    </gazebo>
  </xacro:if>

  <!-- === Sensors === -->
  <!-- Use sensor yaml file if given -->
  <xacro:if value="$(arg yaml_component_generation)">
    <xacro:include filename="$(arg component_xacro_file)" />
    <xacro:yaml_components />

    <!-- Add CPU Cases >
    <xacro:include filename="$(find usn_drone_description)/urdf/cpu_cases.xacro" />
    <xacro:cpu_cases position="-0.15 0 1.53" orientation="0 0 0"/-->
  </xacro:if>

  <!-- Otherwise, add sensors based on enable variables -->
  <xacro:unless value="$(arg yaml_component_generation)">
    <!-- Add a front camera -->
    <xacro:if value="$(arg camera_enabled)">
      <xacro:usn_drone_camera name="front_camera" y="0" x="0.175" z="0.4" P="${radians(15)}" />
    </xacro:if>

    <!-- <xacro:usn_drone_camera name="zed" y="0" x="2" P="${radians(15)}" /> -->

    <!-- Add simulated GPS -->
    <xacro:if value="$(arg gps_enabled)">
      <xacro:usn_drone_gps name="gps_usn_drone" x="-0.85" />
    </xacro:if>

    <!-- Add Simulated IMU -->
    <xacro:if value="$(arg imu_enabled)">
      <xacro:usn_drone_imu name="imu_usn_drone" />
    </xacro:if>

    <!-- Add 3D LIDAR -->
    <xacro:if value="$(arg lidar_enabled)">
      <xacro:lidar name="lidar_usn_drone" y="-0.3" z="-0.2" type="16_beam" />
    </xacro:if>

    <!-- Add P3D ground truth -->
    <xacro:if value="$(arg ground_truth_enabled)">
      <xacro:usn_drone_p3d name="p3d_usn_drone" />
    </xacro:if>

    <!-- Add pinger -->
    <xacro:if value="$(arg pinger_enabled)">
      <xacro:usn_drone_pinger name="pinger" position="1.0 0 -1.0" />
    </xacro:if>

    <!-- Add ball shooter (default pitch angle: ~-60 deg) -->
    <xacro:if value="$(arg ball_shooter_enabled)">
      <xacro:usn_drone_ball_shooter name="ball_shooter" x="0.54" y="0.30" z="1.296" pitch="-1.04" />
    </xacro:if>

    <!-- ==== VRX sensor configuration ==== -->
    <xacro:if value="$(arg vrx_sensors_enabled)">

      <!-- Add CPU Cases >
      <xacro:include filename="$(find usn_drone_description)/urdf/cpu_cases.xacro" />
      <xacro:cpu_cases position="-0.15 0 1.53" orientation="0 0 0"/-->

      <!-- Add a stereo camera pair -->

      <!-- <xacro:usn_drone_camera name="front_left_camera" y="0.1" x="0.75" P="${radians(15)}" /> -->

      <!-- <xacro:usn_drone_camera name="front_right_camera" y="-0.1" x="0.75" P="${radians(15)}" /> -->

     
     
     
     
     
      <!-- <Add an rgb camera > -->
      <!--xacro:wamv_camera name="front_camera_color" y="0.065" x="0.175" z="0.225" P="${radians(15)}" /-->

      
      
      
      
      
      
      
      
      
      <!-- Add simulated GPS -->
      <xacro:usn_drone_gps name="gps_usn_drone" x="0.05" z="0.0" />

      <!-- Add Simulated IMU -->
      <xacro:usn_drone_imu name="imu_usn_drone" x="-0.05" z="0.0" />

      <!-- Add 3D LIDAR -->
      <xacro:lidar name="lidar_usn_drone" type="16_beam" />

      <!-- Add pinger >
      <xacro:usn_drone_pinger name="pinger" position="1.0 0 -1.0" /-->

      <!-- Add ball shooter (default pitch angle: ~-60 deg) >
      <xacro:usn_drone_ball_shooter name="ball_shooter" x="0.54" y="0.30" z="1.296" pitch="-1.04"/-->

    </xacro:if>
  </xacro:unless>
  <gazebo>
    <plugin name="p3d_base_controller" filename="libgazebo_ros_p3d.so">
      <alwaysOn>true</alwaysOn>
      <updateRate>50.0</updateRate>
      <bodyName>usn_drone/base_link</bodyName>
      <topicName>ground_truth/state</topicName>
      <gaussianNoise>0.01</gaussianNoise>
      <frameName>world</frameName>
      <xyzOffsets>0 0 0</xyzOffsets>
      <rpyOffsets>0 0 0</rpyOffsets>
    </plugin>
  </gazebo>

</robot>